<?xml version="1.0"?>
<robot name="jetson_discoverer" xmlns:xacro="http://www.ros.org/wiki/xacro">
	<static>true</static>

	<!-- materials begin -->
	<material name="black">
		<color rgba="0 0 0 1"/>
	</material>

	<material name="white">
		<color rgba="1 1 1 1"/>
	</material>

	<material name="blue">
		<color rgba="0 0 1 1"/>
	</material>

	<material name="green">
		<color rgba="0 0.5 0.5 1"/>
	</material>
	<!-- materials end -->

	<xacro:macro name="m_inertia" params="mass">
		<inertial>
			<mass value="${mass}"/>
			<inertia ixx="0.001" ixy="0.0" ixz="0.0" iyx="0.0" iyy="0.001" iyz="0.0" izx="0.0" izy="0.0" izz="0.001"/>
		</inertial>
	</xacro:macro>

	<xacro:macro name="m_wheel" params="radius_ length_ prefix suffix reflect">
		<link name="${suffix}_wheel">
			<visual>
				<geometry>
					<cylinder radius="${radius_}" length="${length_}"/>
				</geometry>
				<origin xyz="0 0 0" rpy="${pi/2} 0 0"/>
				<material name="black"/>
			</visual>

			<collision>
				<geometry>
					<cylinder radius="${radius_}" length="${length_}"/>
				</geometry>
				<origin xyz="0 0 0" rpy="${pi/2} 0 0"/>

				<surface>
					<friction>
						<ode>
							<kp>1000000.0</kp>
							<kd>1</kd>
							<mu>200.0</mu>
							<mu2>100.0</mu2>
						</ode>
					</friction>
				</surface>
			</collision>

			<xacro:m_inertia mass="0.05"/>
		</link>

		<joint name="${suffix}_wheel_joint" type="continuous">
			<parent link="${prefix}"/>
			<child link="${suffix}_wheel"/>
			<origin xyz="0.03 ${reflect*0.052} -0.015" rpy="0 0 0"/>
			<axis xyz="0 1 0"/>
			<limit effort="30" velocity="0.5"/>
		</joint>	

		<transmission name="${suffix}_wheel_transmission">
			<type>transmission_interface/SimpleTransmission</type>
			<joint name="${suffix}_wheel_joint">
				<hardwareInterface>hardware_interface/VelocityJointInterface</hardwareInterface>
			</joint>

			<actuator name="${suffix}_wheel_motor">
				<hardwareInterface>hardware_interface/VelocityJointInterface</hardwareInterface>
				<mechanicalReduction>1</mechanicalReduction>
			</actuator>			
		</transmission>	
	</xacro:macro>


	<link name="base_link">
	</link>	


	<link name="chassis">
		<visual name='chassis_visual'>
			<geometry>
				<mesh filename="package://jetson_discoverer/meshes/chassis.stl" scale="0.001 0.001 0.001"/>
			</geometry>
			<origin xyz="0 0 0" rpy="${pi/2} 0 ${pi/2}"/>
		</visual>

		<collision name='chassis_collision'>
			<geometry>
				<!-- <box size="0.135 0.09 0.05"/> -->
				<mesh filename="package://jetson_discoverer/meshes/chassis.stl" scale="0.001 0.001 0.001"/>
			</geometry>
			<!-- <origin xyz="0 0 0" rpy="0 0 0"/> -->
			<origin xyz="0 0 0" rpy="${pi/2} 0 ${pi/2}"/>
		</collision>

		<xacro:m_inertia mass="1.0"/>

		<!-- caster wheel -->
		<visual name='caster_visual'>
			<geometry>
				<sphere radius="${0.0625/4}"/>
			</geometry>
			<origin xyz="-0.05 0 -0.025" rpy="0 0 0"/>
			<material name="black"/>
		</visual>

		<collision name='caster_collision'>
			<geometry>
				<sphere radius="${0.0625/4}"/>
			</geometry>
			<origin xyz="-0.05 0 -0.0275" rpy="0 0 0"/>

			<surface>
				<friction>
					<ode>
						<mu>0.2</mu>
						<mu2>0.2</mu2>
			<!-- 			<slip1>1.0</slip1>
						<slip2>1.0</slip2> -->
					</ode>
				</friction>
			</surface>
		</collision>

		<visual name="caster_wheel_base">		
			<geometry>
				<mesh filename="package://jetson_discoverer/meshes/caster_shroud_65mm.stl" scale="0.001 0.001 0.001"/>
			</geometry>
			<origin xyz="0 0 0" rpy="${pi/2} 0 ${pi/2}"/>
			<material name="white"/>
		</visual>

		<!-- camera mount -->
		<visual name="camera_mount">
			<geometry>
				<mesh filename="package://jetson_discoverer/meshes/camera_mount.stl" scale="0.001 0.001 0.001"/>
			</geometry>
			<origin xyz="0 0 0" rpy="${pi/2} 0 -${pi/2}"/>
			<material name="white"/>
		</visual>
		<collision name="camera_mount">
			<geometry>
				<mesh filename="package://jetson_discoverer/meshes/camera_mount.stl" scale="0.001 0.001 0.001"/>
			</geometry>
			<origin xyz="0 0 0" rpy="${pi/2} 0 -${pi/2}"/>
		</collision>

		<!-- jetson + battery -->
		<visual name="jetson">
			<geometry>
				<box size="0.1 0.08 0.015"/>
			</geometry>
			<origin xyz="0 0 0" rpy="0 0 0"/>
			<material name="green"/>
		</visual>

		<collision name="jetson">
			<geometry>
				<box size="0.1 0.08 0.015"/>
			</geometry>
			<origin xyz="0 0 0" rpy="0 0 0"/>
		</collision>

	</link>

	<joint name="base_chassis_joint" type="fixed">
		<parent link="base_link"/>
		<child link="chassis"/>
		<origin xyz="0 0 0" rpy="0 0 0"/>
	</joint>

	<!-- left wheel -->
	<xacro:m_wheel radius_="0.03" length_="0.01" prefix="chassis" suffix="left" reflect="-1"/>

	<!-- right wheel -->
	<xacro:m_wheel radius_="0.03" length_="0.01" prefix="chassis" suffix="right" reflect="1"/>

	<!-- camera -->
	<xacro:include filename="$(find jetson_discoverer)/urdf/camera.gazebo"/>

	<link name="camera_link">
		<visual>
			<geometry>
				<cylinder radius="0.005" length="0.01"/>
			</geometry>
			<origin xyz="0 0 0" rpy="0 ${pi/2+pi/18} 0"/>
			<material name="blue"/>
		</visual>
		<collision>
			<geometry>
				<cylinder radius="0.005" length="0.01"/>
			</geometry>
			<origin xyz="0 0 0" rpy="0 ${pi/2+pi/18} 0"/>
		</collision>

		<xacro:m_inertia mass="0.001"/>
	</link>

	<joint name="cameramount_camera_joint" type="fixed">
		<parent link="chassis"/>
		<child link="camera_link"/>
		<origin xyz="0.05 0 0.015" rpy="0 ${pi/6} 0"/>
	</joint>

	<!-- lidar -->
	<xacro:include filename="$(find jetson_discoverer)/urdf/lidar.gazebo"/>
	<link name="lidar_link">
		<visual>
			<geometry>
				<mesh filename="package://jetson_discoverer/meshes/rplidar_main.stl" scale="0.001 0.001 0.001"/>
			</geometry>
			<origin xyz="0.05 -0.035 0" rpy="${pi/2} 0 ${pi}"/>
			<material name="blue"/>
		</visual>
		<collision>
			<geometry>
<!-- 				<mesh filename="package://jetson_discoverer/meshes/rplidar_main.stl" scale="0.001 0.001 0.001"/>
			 -->			
			<box size="0.02 0.02 0.02"/>
			</geometry>
			<origin xyz="0 0 0.05" rpy="0 0 0"/>
		</collision>

		<xacro:m_inertia mass="0.1"/>
	</link>

	<joint name="chasis_lidar_joint" type="fixed">
		<parent link="chassis"/>
		<child link="lidar_link"/>
		<origin xyz="0 0 0" rpy="0 0 0"/>
	</joint>

	<gazebo>
		<plugin name="gazebo_ros_control" filename="libgazebo_ros_control.so">
			<robotNamespace>/jetson_discoverer/</robotNamespace>
		</plugin>
	</gazebo>



</robot>